Traceback (most recent call last):
  File "/Users/ngcchk/miniconda3/lib/python3.11/site-packages/jupyter_cache/executors/utils.py", line 58, in single_nb_execution
    executenb(
  File "/Users/ngcchk/miniconda3/lib/python3.11/site-packages/nbclient/client.py", line 1305, in execute
    return NotebookClient(nb=nb, resources=resources, km=km, **kwargs).execute()
           ^^^^^^^^^^^^^^^^^^^^^^^^^^^^^^^^^^^^^^^^^^^^^^^^^^^^^^^^^^^^^^^^^^^^^
  File "/Users/ngcchk/miniconda3/lib/python3.11/site-packages/jupyter_core/utils/__init__.py", line 168, in wrapped
    return loop.run_until_complete(inner)
           ^^^^^^^^^^^^^^^^^^^^^^^^^^^^^^
  File "/Users/ngcchk/miniconda3/lib/python3.11/asyncio/base_events.py", line 653, in run_until_complete
    return future.result()
           ^^^^^^^^^^^^^^^
  File "/Users/ngcchk/miniconda3/lib/python3.11/site-packages/nbclient/client.py", line 705, in async_execute
    await self.async_execute_cell(
  File "/Users/ngcchk/miniconda3/lib/python3.11/site-packages/nbclient/client.py", line 1058, in async_execute_cell
    await self._check_raise_for_error(cell, cell_index, exec_reply)
  File "/Users/ngcchk/miniconda3/lib/python3.11/site-packages/nbclient/client.py", line 914, in _check_raise_for_error
    raise CellExecutionError.from_cell_and_msg(cell, exec_reply_content)
nbclient.exceptions.CellExecutionError: An error occurred while executing the following cell:
------------------
%matplotlib inline
import numpy as np
import matplotlib.pyplot as plt
# img1 = plt.imread("D:/Dataset/4.2.03.tiff")
# img1 = plt.imread("~/Dataset/4.2.03.tiff")
img1 = plt.imread("img/handon-c4-test-4-66.tiff") #test.png")
img2h = plt.imread("media/hk2.tiff")
img2t = plt.imread("media/Tk2.tiff")



def showimg(img1):
    '''
"Please open the URL for reading and pass the "
   1522         "result to Pillow, e.g. with "
   1523         "``np.array(PIL.Image.open(urllib.request.urlopen(url)))``."

    '''
    
    print(img1) # no dtype= as in tiff
    print(type(img1))

    plt.imshow(img1)
    plt.show()
    return

showimg(img2h)
showimg(img2t)
------------------


[0;31m---------------------------------------------------------------------------[0m
[0;31mFileNotFoundError[0m                         Traceback (most recent call last)
Cell [0;32mIn[1], line 6[0m
[1;32m      3[0m [38;5;28;01mimport[39;00m [38;5;21;01mmatplotlib[39;00m[38;5;21;01m.[39;00m[38;5;21;01mpyplot[39;00m [38;5;28;01mas[39;00m [38;5;21;01mplt[39;00m
[1;32m      4[0m [38;5;66;03m# img1 = plt.imread("D:/Dataset/4.2.03.tiff")[39;00m
[1;32m      5[0m [38;5;66;03m# img1 = plt.imread("~/Dataset/4.2.03.tiff")[39;00m
[0;32m----> 6[0m img1 [38;5;241m=[39m [43mplt[49m[38;5;241;43m.[39;49m[43mimread[49m[43m([49m[38;5;124;43m"[39;49m[38;5;124;43mimg/handon-c4-test-4-66.tiff[39;49m[38;5;124;43m"[39;49m[43m)[49m [38;5;66;03m#test.png")[39;00m
[1;32m      7[0m img2h [38;5;241m=[39m plt[38;5;241m.[39mimread([38;5;124m"[39m[38;5;124mmedia/hk2.tiff[39m[38;5;124m"[39m)
[1;32m      8[0m img2t [38;5;241m=[39m plt[38;5;241m.[39mimread([38;5;124m"[39m[38;5;124mmedia/Tk2.tiff[39m[38;5;124m"[39m)

File [0;32m~/miniconda3/lib/python3.11/site-packages/matplotlib/pyplot.py:2389[0m, in [0;36mimread[0;34m(fname, format)[0m
[1;32m   2385[0m [38;5;129m@_copy_docstring_and_deprecators[39m(matplotlib[38;5;241m.[39mimage[38;5;241m.[39mimread)
[1;32m   2386[0m [38;5;28;01mdef[39;00m [38;5;21mimread[39m(
[1;32m   2387[0m         fname: [38;5;28mstr[39m [38;5;241m|[39m pathlib[38;5;241m.[39mPath [38;5;241m|[39m BinaryIO, [38;5;28mformat[39m: [38;5;28mstr[39m [38;5;241m|[39m [38;5;28;01mNone[39;00m [38;5;241m=[39m [38;5;28;01mNone[39;00m
[1;32m   2388[0m ) [38;5;241m-[39m[38;5;241m>[39m np[38;5;241m.[39mndarray:
[0;32m-> 2389[0m     [38;5;28;01mreturn[39;00m [43mmatplotlib[49m[38;5;241;43m.[39;49m[43mimage[49m[38;5;241;43m.[39;49m[43mimread[49m[43m([49m[43mfname[49m[43m,[49m[43m [49m[38;5;28;43mformat[39;49m[43m)[49m

File [0;32m~/miniconda3/lib/python3.11/site-packages/matplotlib/image.py:1525[0m, in [0;36mimread[0;34m(fname, format)[0m
[1;32m   1518[0m [38;5;28;01mif[39;00m [38;5;28misinstance[39m(fname, [38;5;28mstr[39m) [38;5;129;01mand[39;00m [38;5;28mlen[39m(parse[38;5;241m.[39murlparse(fname)[38;5;241m.[39mscheme) [38;5;241m>[39m [38;5;241m1[39m:
[1;32m   1519[0m     [38;5;66;03m# Pillow doesn't handle URLs directly.[39;00m
[1;32m   1520[0m     [38;5;28;01mraise[39;00m [38;5;167;01mValueError[39;00m(
[1;32m   1521[0m         [38;5;124m"[39m[38;5;124mPlease open the URL for reading and pass the [39m[38;5;124m"[39m
[1;32m   1522[0m         [38;5;124m"[39m[38;5;124mresult to Pillow, e.g. with [39m[38;5;124m"[39m
[1;32m   1523[0m         [38;5;124m"[39m[38;5;124m``np.array(PIL.Image.open(urllib.request.urlopen(url)))``.[39m[38;5;124m"[39m
[1;32m   1524[0m         )
[0;32m-> 1525[0m [38;5;28;01mwith[39;00m [43mimg_open[49m[43m([49m[43mfname[49m[43m)[49m [38;5;28;01mas[39;00m image:
[1;32m   1526[0m     [38;5;28;01mreturn[39;00m (_pil_png_to_float_array(image)
[1;32m   1527[0m             [38;5;28;01mif[39;00m [38;5;28misinstance[39m(image, PIL[38;5;241m.[39mPngImagePlugin[38;5;241m.[39mPngImageFile) [38;5;28;01melse[39;00m
[1;32m   1528[0m             pil_to_array(image))

File [0;32m~/miniconda3/lib/python3.11/site-packages/PIL/Image.py:3218[0m, in [0;36mopen[0;34m(fp, mode, formats)[0m
[1;32m   3215[0m     filename [38;5;241m=[39m fp
[1;32m   3217[0m [38;5;28;01mif[39;00m filename:
[0;32m-> 3218[0m     fp [38;5;241m=[39m [43mbuiltins[49m[38;5;241;43m.[39;49m[43mopen[49m[43m([49m[43mfilename[49m[43m,[49m[43m [49m[38;5;124;43m"[39;49m[38;5;124;43mrb[39;49m[38;5;124;43m"[39;49m[43m)[49m
[1;32m   3219[0m     exclusive_fp [38;5;241m=[39m [38;5;28;01mTrue[39;00m
[1;32m   3221[0m [38;5;28;01mtry[39;00m:

[0;31mFileNotFoundError[0m: [Errno 2] No such file or directory: 'img/handon-c4-test-4-66.tiff'

