Traceback (most recent call last):
  File "/Users/ngcchk/miniconda3/envs/d2ljb/lib/python3.9/site-packages/jupyter_cache/executors/utils.py", line 58, in single_nb_execution
    executenb(
  File "/Users/ngcchk/miniconda3/envs/d2ljb/lib/python3.9/site-packages/nbclient/client.py", line 1305, in execute
    return NotebookClient(nb=nb, resources=resources, km=km, **kwargs).execute()
  File "/Users/ngcchk/miniconda3/envs/d2ljb/lib/python3.9/site-packages/jupyter_core/utils/__init__.py", line 173, in wrapped
    return loop.run_until_complete(inner)
  File "/Users/ngcchk/miniconda3/envs/d2ljb/lib/python3.9/asyncio/base_events.py", line 647, in run_until_complete
    return future.result()
  File "/Users/ngcchk/miniconda3/envs/d2ljb/lib/python3.9/site-packages/nbclient/client.py", line 705, in async_execute
    await self.async_execute_cell(
  File "/Users/ngcchk/miniconda3/envs/d2ljb/lib/python3.9/site-packages/nbclient/client.py", line 1058, in async_execute_cell
    await self._check_raise_for_error(cell, cell_index, exec_reply)
  File "/Users/ngcchk/miniconda3/envs/d2ljb/lib/python3.9/site-packages/nbclient/client.py", line 914, in _check_raise_for_error
    raise CellExecutionError.from_cell_and_msg(cell, exec_reply_content)
nbclient.exceptions.CellExecutionError: An error occurred while executing the following cell:
------------------
from main import example_covid


------------------


[0;31m---------------------------------------------------------------------------[0m
[0;31mModuleNotFoundError[0m                       Traceback (most recent call last)
Cell [0;32mIn[1], line 1[0m
[0;32m----> 1[0m [38;5;28;01mfrom[39;00m [38;5;21;01mmain[39;00m [38;5;28;01mimport[39;00m example_covid

File [0;32m~/Documents/Github/gpd2-win-unity1/ipadred-rain/imgno_book1/imgnobk3/main/example_covid.py:7[0m
[1;32m      1[0m [38;5;66;03m# -*- coding: utf-8 -*-[39;00m
[1;32m      2[0m [38;5;124;03m"""Sample example used for testing purposes[39;00m
[1;32m      3[0m [38;5;124;03msee https://github.com/nf1s/covid/blob/master/example.py[39;00m
[1;32m      4[0m 
[1;32m      5[0m [38;5;124;03m"""[39;00m
[0;32m----> 7[0m [38;5;28;01mfrom[39;00m [38;5;21;01mcovid[39;00m [38;5;28;01mimport[39;00m Covid
[1;32m     10[0m [38;5;28;01mdef[39;00m [38;5;21mrun_mod[39m(message, covid_source[38;5;241m=[39m[38;5;124m"[39m[38;5;124mworldometers[39m[38;5;124m"[39m):
[1;32m     11[0m     [38;5;28mprint[39m([38;5;124m"[39m[38;5;124m===============================================[39m[38;5;124m"[39m)

[0;31mModuleNotFoundError[0m: No module named 'covid'

