Traceback (most recent call last):
  File "/Users/ngcchk/miniconda3/lib/python3.11/site-packages/jupyter_cache/executors/utils.py", line 58, in single_nb_execution
    executenb(
  File "/Users/ngcchk/miniconda3/lib/python3.11/site-packages/nbclient/client.py", line 1305, in execute
    return NotebookClient(nb=nb, resources=resources, km=km, **kwargs).execute()
           ^^^^^^^^^^^^^^^^^^^^^^^^^^^^^^^^^^^^^^^^^^^^^^^^^^^^^^^^^^^^^^^^^^^^^
  File "/Users/ngcchk/miniconda3/lib/python3.11/site-packages/jupyter_core/utils/__init__.py", line 168, in wrapped
    return loop.run_until_complete(inner)
           ^^^^^^^^^^^^^^^^^^^^^^^^^^^^^^
  File "/Users/ngcchk/miniconda3/lib/python3.11/asyncio/base_events.py", line 653, in run_until_complete
    return future.result()
           ^^^^^^^^^^^^^^^
  File "/Users/ngcchk/miniconda3/lib/python3.11/site-packages/nbclient/client.py", line 705, in async_execute
    await self.async_execute_cell(
  File "/Users/ngcchk/miniconda3/lib/python3.11/site-packages/nbclient/client.py", line 1058, in async_execute_cell
    await self._check_raise_for_error(cell, cell_index, exec_reply)
  File "/Users/ngcchk/miniconda3/lib/python3.11/site-packages/nbclient/client.py", line 914, in _check_raise_for_error
    raise CellExecutionError.from_cell_and_msg(cell, exec_reply_content)
nbclient.exceptions.CellExecutionError: An error occurred while executing the following cell:
------------------
import os
os.listdir("/var/mobile/Containers/Data/Application/03AF0984-E7D3-402A-AC98-38B4F54E4D14/Library/Application Support/com.rationalmatter.junoapp/python-home/lib/python3.10/site-packages/matplotlib/backends/")

'''
['_backend_gtk.py',
 'backend_template.py',
 'backend_qtcairo.py',
 'backend_qt.py',
 'backend_gtk3cairo.py',
 'backend_tkagg.py',
 'backend_gtk4agg.py',
 'web_backend',
 'backend_qt5agg.py',
 'backend_qt5.py',
 'backend_gtk3agg.py',
 'backend_cairo.py',
 'backend_pdf.py',
 'backend_wxagg.py',
 'backend_pgf.py',
 'backend_mixed.py',
 'backend_macosx.py',
 'backend_gtk4.py',
 '__init__.py',
 '__pycache__',
 'qt_editor',
 'backend_tkcairo.py',
 'backend_gtk3.py',
 'backend_wxcairo.py',
 'backend_nbagg.py',
 'backend_webagg_core.py',
 'backend_gtk4cairo.py',
 'backend_wx.py',
 'backend_qt5cairo.py',
 '_backend_tk.py',
 'qt_compat.py',
 'backend_svg.py',
 '_backend_pdf_ps.py',
 'backend_webagg.py',
 'backend_ps.py',
 'backend_qtagg.py',
 'backend_agg.py']
'''
------------------


[0;31m---------------------------------------------------------------------------[0m
[0;31mFileNotFoundError[0m                         Traceback (most recent call last)
Cell [0;32mIn[2], line 2[0m
[1;32m      1[0m [38;5;28;01mimport[39;00m [38;5;21;01mos[39;00m
[0;32m----> 2[0m [43mos[49m[38;5;241;43m.[39;49m[43mlistdir[49m[43m([49m[38;5;124;43m"[39;49m[38;5;124;43m/var/mobile/Containers/Data/Application/03AF0984-E7D3-402A-AC98-38B4F54E4D14/Library/Application Support/com.rationalmatter.junoapp/python-home/lib/python3.10/site-packages/matplotlib/backends/[39;49m[38;5;124;43m"[39;49m[43m)[49m
[1;32m      4[0m [38;5;124;03m'''[39;00m
[1;32m      5[0m [38;5;124;03m['_backend_gtk.py',[39;00m
[1;32m      6[0m [38;5;124;03m 'backend_template.py',[39;00m
[0;32m   (...)[0m
[1;32m     41[0m [38;5;124;03m 'backend_agg.py'][39;00m
[1;32m     42[0m [38;5;124;03m'''[39;00m

[0;31mFileNotFoundError[0m: [Errno 2] No such file or directory: '/var/mobile/Containers/Data/Application/03AF0984-E7D3-402A-AC98-38B4F54E4D14/Library/Application Support/com.rationalmatter.junoapp/python-home/lib/python3.10/site-packages/matplotlib/backends/'

